Workbook

Sheet ROUTE-AREA SETTINGS
A1: JOLEO TRANSPORT – ROUTE & AREA REFERENCE (LUZON)
A2: Area Category | B2: Sample Destinations | C2: Distance Range (km) | D2: Surcharge (₱) | E2: Est. Toll (₱) | F2: Remarks
A3: Metro Manila | B3: Caloocan, Manila, Quezon City, Makati, Pasig, Taguig, Mandaluyong, Marikina, Pasay, Parañaque, Las Piñas, Muntinlupa, Valenzuela, Malabon, Navotas | C3: 1 – 30 km | D3: 0 | E3: 0 | F3: No surcharge within Metro Manila
A4: Central Luzon | B4: Bulacan, Pampanga, Tarlac, Nueva Ecija, Zambales, Bataan, Aurora | C4: 31 – 200 km | D4: 500 | E4: 500 | F4: Out-of-town surcharge applies
A5: CALABARZON | B5: Cavite, Laguna, Batangas, Rizal, Quezon Province | C5: 30 – 200 km | D5: 500 | E5: 300 | F5: Out-of-town surcharge applies
A6: North Luzon | B6: Pangasinan, La Union, Ilocos Norte, Ilocos Sur, Benguet, Baguio City, Mountain Province | C6: 200 – 500 km | D6: 1500 | E6: 800 | F6: Long-distance surcharge applies
A7: South Luzon | B7: Quezon (Lucena, Tayabas), Bondoc Peninsula | C7: 150 – 350 km | D7: 1000 | E7: 400 | F7: Long-distance surcharge applies
A8: Bicol Region | B8: Camarines Norte, Camarines Sur (Naga), Albay (Legazpi), Sorsogon, Masbate | C8: 400 – 700 km | D8: 1500 | E8: 1000 | F8: Long-haul; overnight driver accommodation may be needed
A9: Mindoro | B9: Oriental Mindoro, Occidental Mindoro (via ferry) | C9: 200 – 400 km | D9: 2000 | E9: 500 | F9: Ferry cost separate; confirm availability
A10: Palawan (via land+ferry) | B10: Puerto Princesa (requires sea transport) | C10: 500+ km | D10: 3000 | E10: 1000 | F10: Long-haul; special quotation strongly recommended

Sheet HELPER MASTERLIST
A1: JOLEO TRANSPORT – HELPER MASTERLIST
A2: Helper ID | B2: Helper Name | C2: Daily Rate (₱) | D2: OT Rate (₱/hr) | E2: Status | F2: Remarks
A3: 2014035 | B3: BONTIGAO, FRANCIS | C3: 600 | D3: 100 | E3: Active
A4: 2013001 | B4: CABANIGAN, JOEL | C4: 600 | D4: 100 | E4: Active
A5: 2017007 | B5: CULA, JORDAN | C5: 600 | D5: 100 | E5: Active
A6: 2026031 | B6: LANUZA, JC | C6: 600 | D6: 100 | E6: Active
A7: 2017003 | B7: LIBONGCOGON, RENIL | C7: 600 | D7: 100 | E7: Active
A8: 2023007 | B8: ONDOC, JUNNIFER | C8: 600 | D8: 100 | E8: Active
A9: 2025110 | B9: ROQUE, JOHN | C9: 600 | D9: 100 | E9: Active

Sheet DRIVER MASTERLIST
A1: JOLEO TRANSPORT – DRIVER MASTERLIST
A2: Driver ID | B2: Driver Name | C2: Daily Rate (₱) | D2: OT Rate (₱/hr) | E2: Status | F2: Remarks
A3: 2013030 | B3: CARAGAY, ROGELIO JR. | C3: 800 | D3: 150 | E3: Active
A4: 2026031 | B4: CAPALARAN, RONEL | C4: 800 | D4: 150 | E4: Active
A5: 2016034 | B5: CORAÑES, RODNEY | C5: 800 | D5: 150 | E5: Active
A6: 2010012 | B6: IGNACIO, PHILIP | C6: 800 | D6: 150 | E6: Active
A7: 2016032 | B7: LORETO, ANTONIO | C7: 800 | D7: 150 | E7: Active
A8: 2025103 | B8: CASINOVA, ARMANDO | C8: 800 | D8: 150 | E8: Active
A9: 2025025 | B9: LIBONGCOGON, RONALD | C9: 800 | D9: 150 | E9: Active
A10: 2013001 | B10: PREDILLA, NILO | C10: 800 | D10: 150 | E10: Active
A11: 2018007 | B11: PREDILLA, ALLAN JAY | C11: 800 | D11: 150 | E11: Active

Sheet TRUCK MASTERLIST
A1: JOLEO TRANSPORT – TRUCK MASTERLIST
A2: Truck ID | B2: Plate No. | C2: Truck Type | D2: Size (ft) | E2: Wheel Type | F2: Fuel Cons. (km/L) | G2: Min Base Rate (₱) | H2: Daily Rate (₱) | I2: Excess Hour Rate (₱/hr) | J2: Status | K2: Remarks
A3: V5 | B3: XHR 788 | C3: 10 ftr - 4 wheels | D3: 10 | E3: 4-wheel | F3: 7.5 | G3: ='RATE SETTINGS'!$B$38 -> 2500 | H3: ='RATE SETTINGS'!$B$38 -> 2500 | I3: 150 | J3: Active
A4: V6 | B4: REP 141 | C4: 14 ftr - 6 wheels | D4: 14 | E4: 6-wheel | F4: 5 | G4: ='RATE SETTINGS'!$B$41 -> 4500 | H4: ='RATE SETTINGS'!$B$41 -> 4500 | I4: 200 | J4: Active
A5: V7 | B5: RFZ 534 | C5: 16 ftr - 6 wheels | D5: 16 | E5: 6-wheel | F5: 4.5 | G5: ='RATE SETTINGS'!$B$42 -> 6000 | H5: ='RATE SETTINGS'!$B$42 -> 6000 | I5: 250 | J5: Active
A6: V9 | B6: XKD 180 | C6: 12 ftr - 6 wheels | D6: 12 | E6: 6-wheel | F6: 6 | G6: ='RATE SETTINGS'!$B$40 -> 3500 | H6: ='RATE SETTINGS'!$B$40 -> 3500 | I6: 175 | J6: Active
A7: V10 | B7: RJB 646 | C7: 20 ftr - 6 wheels | D7: 20 | E7: 6-wheel | F7: 3.5 | G7: ='RATE SETTINGS'!$B$43 -> 8000 | H7: ='RATE SETTINGS'!$B$43 -> 8000 | I7: 300 | J7: Active
A8: V12 | B8: TQO 775 | C8: 14 ftr - 6 wheels | D8: 14 | E8: 6-wheel | F8: 5 | G8: ='RATE SETTINGS'!$B$41 -> 4500 | H8: ='RATE SETTINGS'!$B$41 -> 4500 | I8: 200 | J8: Active
A9: V13 | B9: UWI 887 | C9: 14 ftr - 6 wheels | D9: 14 | E9: 6-wheel | F9: 5 | G9: ='RATE SETTINGS'!$B$41 -> 4500 | H9: ='RATE SETTINGS'!$B$41 -> 4500 | I9: 200 | J9: Active
A10: V15 | B10: RBH 578 | C10: 10 ftr - 6 wheels | D10: 10 | E10: 6-wheel | F10: 6.5 | G10: ='RATE SETTINGS'!$B$39 -> 3000 | H10: ='RATE SETTINGS'!$B$39 -> 3000 | I10: 150 | J10: Active
A11: V16 | B11: UCC 523 | C11: 10 ftr - 4 wheels | D11: 10 | E11: 4-wheel | F11: 7.5 | G11: ='RATE SETTINGS'!$B$38 -> 2500 | H11: ='RATE SETTINGS'!$B$38 -> 2500 | I11: 150 | J11: Active
A12: V17 | B12: WLL 732 | C12: 10 ftr - 4 wheels | D12: 10 | E12: 4-wheel | F12: 7.5 | G12: ='RATE SETTINGS'!$B$38 -> 2500 | H12: ='RATE SETTINGS'!$B$38 -> 2500 | I12: 150 | J12: Active
A13: V18 | B13: RJE 141 | C13: 10 ftr - 4 wheels | D13: 10 | E13: 4-wheel | F13: 7.5 | G13: ='RATE SETTINGS'!$B$38 -> 2500 | H13: ='RATE SETTINGS'!$B$38 -> 2500 | I13: 150 | J13: Active
A14: V20 | B14: URR 575 | C14: 10 ftr - 4 wheels | D14: 10 | E14: 4-wheel | F14: 7.5 | G14: ='RATE SETTINGS'!$B$38 -> 2500 | H14: ='RATE SETTINGS'!$B$38 -> 2500 | I14: 150 | J14: Active
A15: V21 | B15: RHY 366 | C15: 10 ftr - 6 wheels | D15: 10 | E15: 6-wheel | F15: 6.5 | G15: ='RATE SETTINGS'!$B$39 -> 3000 | H15: ='RATE SETTINGS'!$B$39 -> 3000 | I15: 150 | J15: Active
A16: V22 | B16: RHV 542 | C16: 14 ftr - 6 wheels | D16: 14 | E16: 6-wheel | F16: 5 | G16: ='RATE SETTINGS'!$B$41 -> 4500 | H16: ='RATE SETTINGS'!$B$41 -> 4500 | I16: 200 | J16: Active
A17: V23 | B17: RJP 723 | C17: 10 ftr - 4 wheels | D17: 10 | E17: 4-wheel | F17: 7.5 | G17: ='RATE SETTINGS'!$B$38 -> 2500 | H17: ='RATE SETTINGS'!$B$38 -> 2500 | I17: 150 | J17: Active
A18: ELF1 | B18: XAM 959 | C18: 14 ftr - 6 wheels | D18: 14 | E18: 6-wheel | F18: 5 | G18: ='RATE SETTINGS'!$B$41 -> 4500 | H18: ='RATE SETTINGS'!$B$41 -> 4500 | I18: 200 | J18: Active
A19: ELF2 | B19: XSH 957 | C19: 16 ftr - 6 wheels (Dropside) | D19: 16 | E19: 6-wheel | F19: 4.5 | G19: ='RATE SETTINGS'!$B$44 -> 5000 | H19: ='RATE SETTINGS'!$B$44 -> 5000 | I19: 250 | J19: Active
A21: Fuel Consumption Defaults: 10ft-4w=7.5 km/L | 10ft-6w=6.5 | 12ft-6w=6.0 | 14ft-6w=5.0 | 16ft-6w=4.5 | 20ft-6w=3.5 | Dropside=4.5

Sheet RATE SETTINGS
A1: JOLEO TRANSPORT – RATE SETTINGS
A2: Edit column B values only. All computation sheets reference these settings automatically.
A3: SETTING | B3: INPUT VALUE | C3: NOTES / EXPLANATION | D3: SUGGESTED MIN | E3: SUGGESTED MAX
A4: FUEL & OPERATIONS
A5: Diesel Price per Liter | B5: 70 | C5: Update as pump price changes | D5: 55 | E5: 90
A6: Fuel Surcharge % | B6: 0.05 | C6: Added on top of raw fuel cost | D6: 0 | E6: 0.15
A7: MANPOWER RATES
A8: Driver Daily Rate | B8: 800 | C8: 8-hour standard shift | D8: 600 | E8: 1200
A9: Driver Overtime Rate / hr | B9: 150 | C9: Per hour beyond 8 hours | D9: 100 | E9: 250
A10: Helper Daily Rate | B10: 600 | C10: 8-hour standard shift | D10: 400 | E10: 900
A11: Helper Overtime Rate / hr | B11: 100 | C11: Per hour beyond 8 hours | D11: 75 | E11: 175
A12: Additional Helper Rate | B12: 600 | C12: Rate for each extra helper beyond the first | D12: 400 | E12: 900
A13: SERVICE INCLUSIONS
A14: Standard Included Hours | B14: 8 | C14: Hours included in base booking | D14: 6 | E14: 10
A15: Additional Hour Rate | B15: 350 | C15: Charged per excess hour | D15: 200 | E15: 600
A16: Additional Drop-off Charge | B16: 300 | C16: Per extra drop-off beyond the first | D16: 150 | E16: 500
A17: SPECIAL SERVICE FEES
A18: Condo Handling Fee | B18: 500 | C18: Condo move-in/out surcharge | D18: 300 | E18: 1000
A19: Catering Handling Fee | B19: 400 | C19: Catering delivery surcharge | D19: 200 | E19: 800
A20: Loading/Unloading Fee | B20: 0 | C20: 0 if included in base rate | D20: 0 | E20: 2000
A21: Night Delivery Surcharge | B21: 500 | C21: Deliveries after 9PM | D21: 300 | E21: 1000
A22: Waiting Time Charge / hr | B22: 200 | C22: Per hour of waiting time on site | D22: 100 | E22: 400
A23: DISTANCE SURCHARGES
A24: Out-of-Town Surcharge | B24: 500 | C24: Beyond Metro Manila boundaries | D24: 300 | E24: 1000
A25: Long-Distance Surcharge | B25: 1500 | C25: Trips exceeding 200 km one way | D25: 1000 | E25: 3000
A26: Distance Rate per km | B26: 12 | C26: Applied to estimated total distance | D26: 8 | E26: 20
A27: COST ALLOCATIONS
A28: Maintenance % of Base Rate | B28: 0.08 | C28: Provision for truck upkeep | D28: 0.05 | E28: 0.12
A29: Overhead % of Direct Costs | B29: 0.1 | C29: Admin, office, insurance allocation | D29: 0.07 | E29: 0.15
A30: Contingency % of Direct Costs | B30: 0.03 | C30: Buffer for unexpected costs | D30: 0.02 | E30: 0.05
A31: PROFIT MARGINS
A32: Floor Profit Margin % | B32: 0.15 | C32: Minimum acceptable margin | D32: 0.1 | E32: 0.2
A33: Target Profit Margin % | B33: 0.25 | C33: Ideal per-booking margin | D33: 0.2 | E33: 0.35
A34: Ceiling Profit Margin % | B34: 0.4 | C34: Maximum ceiling for competitive pricing | D34: 0.3 | E34: 0.5
A35: TAX
A36: VAT Rate | B36: 0.12 | C36: Standard Philippine VAT | D36: 0.12 | E36: 0.12
A37: MINIMUM BASE RATES BY TRUCK TYPE
A38: 10 ft – 4 Wheeler Min Rate | B38: 2500 | C38: Metro Manila short haul | D38: 2000 | E38: 4000
A39: 10 ft – 6 Wheeler Min Rate | B39: 3000 | C39: Metro Manila short haul | D39: 2500 | E39: 5000
A40: 12 ft – 6 Wheeler Min Rate | B40: 3500 | C40: Medium load, short haul | D40: 3000 | E40: 5500
...

Sheet PRICE COMPUTATION
B1: JOLEO TRANSPORT
B2: TRUCKING PRICE COMPUTATION SHEET
B3: Brgy. 164, Caloocan City | Serving all points in Luzon | ★ Input cells are highlighted in YELLOW ★
B5: SECTION A – BOOKING INFORMATION
B6: Date of Quotation | F6: Quotation No.
B7: Client / Company Name | F7: Contact Person
B8: Service Type | D8: Lipat-Bahay / House Moving
B9: Pick-up Point | F9: Drop-off Point
B10: Route / Destination Area | F10: Estimated Distance (km) | G10: 100
B11: Estimated Travel Time | F11: Number of Drop-offs | G11: 2
B13: SECTION B – TRUCK & CREW SELECTION
B14: Truck Selected | D14: V6 | F14: Number of Helpers | G14: 2
B15: Driver Selected | D15: CAPALARAN, RONEL | F15: Helper Selected | G15: CULA, JORDAN
B17: SECTION C – JOB DETAILS & SERVICE FLAGS
B18: Included Hours in Booking | D18: 8 | F18: Condo Service? (Yes/No) | G18: Yes
B19: Estimated Job Hours | F19: Catering Service? (Yes/No) | G19: No
B20: Toll Fee (₱) | F20: Night Delivery? (Yes/No) | G20: No
B21: Parking Fee (₱) | F21: Additional Helper? (Yes/No) | G21: No
B22: Fuel Price Override (₱/L) | F22: Need Overtime / Excess Hours? | G22: No
B23: Discount Amount (₱) | F23: Out-of-Town Trip? (Yes/No) | G23: Yes
B24: Long-Distance Trip? (>200 km) | D24: No | F24: VAT Option | G24: VAT-Inclusive
B26: SECTION D – AUTOMATIC PRICE COMPUTATION
B27: COST COMPONENT | D27: COMPUTATION BASIS / NOTES | F27: AMOUNT (₱)
B28: 1. Truck Base Rate | D28: Min rate for selected truck type from Rate Settings | F28: =IFERROR(_xludf.XLOOKUP(D14,'TRUCK MASTERLIST'!$A$3:$A$19,'TRUCK MASTERLIST'!$G$3:$G$19,0),0) -> 0
B29: 2. Distance Charge | D29: Estimated km (G10) × distance rate/km ('RATE SETTINGS'!$B$26) | F29: =G10*'RATE SETTINGS'!$B$26 -> 1200
B30: 3. Fuel Cost (round-trip) | D30: (Distance ÷ fuel consumption) × diesel price × 2 × (1 + surcharge%) | F30: =IFERROR((G10/IFERROR(_xludf.XLOOKUP(D14,'TRUCK MASTERLIST'!$A$3:$A$19,'TRUCK MASTERLIST'!$F$3:$F$19,0),5))*(IF(D22="",'RATE SETTINGS'!$B$5,D22))*2*(1+'RATE SETTINGS'!$B$6),0) -> 2940
B31: 4. Driver Cost | D31: Daily rate for selected driver | F31: =IFERROR(_xludf.XLOOKUP(D15,'DRIVER MASTERLIST'!$B$3:$B$11,'DRIVER MASTERLIST'!$C$3:$C$11,0),'RATE SETTINGS'!$B$8) -> 800
B32: 5. Helper Cost | D32: Helper daily rate × number of helpers | F32: =IFERROR(_xludf.XLOOKUP(G15,'HELPER MASTERLIST'!$B$3:$B$9,'HELPER MASTERLIST'!$C$3:$C$9,0),'RATE SETTINGS'!$B$10)*MAX(1,G14) -> 1200
B33: 6. Additional Helper | D33: Charged if Additional Helper flag = Yes | F33: =IF(G21="Yes",'RATE SETTINGS'!$B$12,0) -> 0
B34: 7. Excess Hours Cost | D34: MAX(0, job hrs - included hrs) × additional hour rate | F34: =IF(G22="Yes",MAX(0,D19-D18)*'RATE SETTINGS'!$B$15,0) -> 0
B35: 8. Extra Drop-off Charge | D35: Each drop-off beyond first is charged extra | F35: =MAX(0,G11-1)*'RATE SETTINGS'!$B$16 -> 300
B36: 9. Condo Handling Fee | D36: Building access / elevator coordination surcharge | F36: =IF(G18="Yes",'RATE SETTINGS'!$B$18,0) -> 500
B37: 10. Catering Handling Fee | D37: Special handling for catering deliveries | F37: =IF(G19="Yes",'RATE SETTINGS'!$B$19,0) -> 0
B38: 11. Loading / Unloading Fee | D38: Per Rate Settings (0 if included in base rate) | F38: ='RATE SETTINGS'!$B$20 -> 0
B39: 12. Night Delivery Surcharge | D39: Applied for trips starting after 9PM | F39: =IF(G20="Yes",'RATE SETTINGS'!$B$21,0) -> 0
B40: 13. Out-of-Town Surcharge | D40: Applied for routes beyond Metro Manila | F40: =IF(G23="Yes",'RATE SETTINGS'!$B$24,0) -> 500
B41: 14. Long-Distance Surcharge | D41: Applied for trips exceeding 200 km | F41: =IF(D24="Yes",'RATE SETTINGS'!$B$25,0) -> 0
B42: 15. Toll & Parking | D42: Toll fee (D20) + Parking fee (D21) | F42: =IFERROR(D20,0)+IFERROR(D21,0) -> 0
B43: 16. Maintenance Allowance | D43: Maintenance % × base truck rate (F28) | F43: =F28*'RATE SETTINGS'!$B$28 -> 0
B44: DIRECT COST SUBTOTAL (before overhead & profit) | F44: =SUM(F28:F43) -> 7440
...

Sheet QUOTATION SUMMARY
B1: JOLEO TRANSPORT
B2: SERVICE QUOTATION
B3: Brgy. 164, Caloocan City, Metro Manila | Tel: [Insert] | Email: [Insert]
B5: CLIENT & BOOKING DETAILS
B6: Quotation Date | C6: ='PRICE COMPUTATION'!D6 -> 0
B7: Client Name | C7: ='PRICE COMPUTATION'!D7 -> 0
B8: Contact Person | C8: ='PRICE COMPUTATION'!G7 -> 0
B9: Service Type | C9: ='PRICE COMPUTATION'!D8 -> Lipat-Bahay / House Moving
B10: Pick-up Point | C10: ='PRICE COMPUTATION'!D9 -> 0
B11: Drop-off Point | C11: ='PRICE COMPUTATION'!G9 -> 0
B12: Route / Area | C12: ='PRICE COMPUTATION'!D10 -> 0
B13: Est. Distance | C13: =IFERROR('PRICE COMPUTATION'!G10&" km","") -> 100 km
B15: TRUCK & CREW
B16: Truck Selected | C16: ='PRICE COMPUTATION'!D14 -> V6
B17: Driver | C17: ='PRICE COMPUTATION'!D15 -> CAPALARAN, RONEL
B18: Helper | C18: ='PRICE COMPUTATION'!G15 -> CULA, JORDAN
B19: No. of Helpers | C19: ='PRICE COMPUTATION'!G14 -> 2
B20: Included Hours | C20: =IFERROR('PRICE COMPUTATION'!D18&" hours","") -> 8 hours
B22: SERVICE INCLUSIONS
B23: ✅ Door-to-door truck transportation ✅ Driver and helper(s) as specified ✅ Standard loading and unloading assistance ✅ Toll and parking fees as estimated ✅ Service within agreed hours and route
B29: EXCLUSIONS
B30: ❌ Packing materials (unless arranged separately) ❌ Undeclared items requiring special handling ❌ Excess hours beyond agreed period (charged extra)
B34: PRICING SUMMARY
B35: Floor Price (Min Acceptable) | C35: ='PRICE COMPUTATION'!F49 -> 9890.8235
B36: Target Price (Recommended) | C36: ='PRICE COMPUTATION'!F50 -> 11209.6
B37: Ceiling Price (Max Market) | C37: ='PRICE COMPUTATION'!F51 -> 14012
B39: ✅ QUOTED PRICE TO CLIENT
B40: ='PRICE COMPUTATION'!F57 -> 11209.6
B41: VAT Option | C41: ='PRICE COMPUTATION'!G24 -> VAT-Inclusive
B42: VAT Amount | C42: ='PRICE COMPUTATION'!F55 -> 1201.0286
B44: TERMS & CONDITIONS
B45: 1. This quotation is valid for 7 days from date of issue. 2. A 50% deposit may be required upon booking confirmation. 3. Final billing based on actual distance, hours, and scope of work. 4. Excess hours, extra drop-offs, and out-of-scope items billed separately. 5. Joleo Transport is not liable for improperly packed or undeclared items. 6. Route and scheduling subject to truck availability at time of booking.
B52: Authorized by: __________________________ | Date: __________________________
B53: Prepared by Joleo Transport Operations Team
